<?xml version="1.0"?>
<robot xmlns:xacro="http://www.ros.org/wiki/xacro" name="rockerbogie_rover">

  <!-- Base Parameters -->
  <xacro:property name="base_length" value="0.5" />
  <xacro:property name="base_width" value="0.4" />
  <xacro:property name="base_height" value="0.1" />
  <xacro:property name="wheel_radius" value="0.15" />
  <xacro:property name="wheel_width" value="0.08" />

  <!-- Base Link -->
  <link name="base_link">
    <inertial>
      <mass value="5.0"/>
      <inertia ixx="0.1" ixy="0" ixz="0" iyy="0.1" iyz="0" izz="0.1"/>
    </inertial>
    <visual>
      <geometry>
        <box size="${base_length} ${base_width} ${base_height}"/>
      </geometry>
    </visual>
    <collision>
      <geometry>
        <box size="${base_length} ${base_width} ${base_height}"/>
      </geometry>
    </collision>
  </link>

  <!-- Rocker-Bogie Suspension -->
  <xacro:macro name="rocker_bogie_assembly" params="prefix parent reflect">
    
    <!-- Rocker Joint & Link -->
    <joint name="${prefix}_rocker_joint" type="revolute">
      <parent link="${parent}"/>
      <child link="${prefix}_rocker_link"/>
      <origin xyz="${0.2*reflect} 0 0" rpy="0 0 0"/>
      <axis xyz="0 1 0"/>
      <limit lower="-1.0" upper="1.0" effort="100" velocity="1.0"/>
      <dynamics damping="10.0"/>
    </joint>

    <link name="${prefix}_rocker_link">
      <inertial>
        <mass value="1.5"/>
        <inertia ixx="0.05" ixy="0" ixz="0" iyy="0.05" iyz="0" izz="0.05"/>
      </inertial>
      <visual>
        <geometry>
          <cylinder radius="0.03" length="0.3"/>
        </geometry>
      </visual>
    </link>

    <!-- Bogie Joint & Link -->
    <joint name="${prefix}_bogie_joint" type="revolute">
      <parent link="${prefix}_rocker_link"/>
      <child link="${prefix}_bogie_link"/>
      <origin xyz="0.15 0 0" rpy="0 0 0"/>
      <axis xyz="0 1 0"/>
      <limit lower="-0.5" upper="0.5" effort="100" velocity="1.0"/>
      <dynamics damping="8.0"/>
    </joint>

    <link name="${prefix}_bogie_link">
      <inertial>
        <mass value="1.0"/>
        <inertia ixx="0.03" ixy="0" ixz="0" iyy="0.03" iyz="0" izz="0.03"/>
      </inertial>
      <visual>
        <geometry>
          <cylinder radius="0.025" length="0.25"/>
        </geometry>
      </visual>
    </link>

    <!-- Front & Rear Wheels -->
    <xacro:wheel parent="${prefix}_rocker_link" suffix="front" xyz="0.25 0 0"/>
    <xacro:wheel parent="${prefix}_bogie_link" suffix="rear" xyz="0.25 0 0"/>
  </xacro:macro>

  <!-- Wheel Macro -->
  <xacro:macro name="wheel" params="parent suffix xyz">
    <joint name="${parent}_${suffix}_wheel_joint" type="continuous">
      <parent link="${parent}"/>
      <child link="${parent}_${suffix}_wheel"/>
      <origin xyz="${xyz}" rpy="0 1.5708 0"/>
      <axis xyz="0 0 1"/>
    </joint>

    <link name="${parent}_${suffix}_wheel">
      <inertial>
        <mass value="0.5"/>
        <inertia ixx="0.01" ixy="0" ixz="0" iyy="0.01" iyz="0" izz="0.01"/>
      </inertial>
      <visual>
        <geometry>
          <cylinder radius="${wheel_radius}" length="${wheel_width}"/>
        </geometry>
      </visual>
      <collision>
        <geometry>
          <cylinder radius="${wheel_radius}" length="${wheel_width}"/>
        </geometry>
      </collision>
    </link>

    <!-- Gazebo ROS Control -->
    <gazebo reference="${parent}_${suffix}_wheel">
      <mu1>1.5</mu1>
      <mu2>1.5</mu2>
      <kp>1000000.0</kp>
      <kd>100.0</kd>
    </gazebo>

    <transmission name="${parent}_${suffix}_wheel_trans">
      <type>transmission_interface/SimpleTransmission</type>
      <joint name="${parent}_${suffix}_wheel_joint">
        <hardwareInterface>hardware_interface/VelocityJointInterface</hardwareInterface>
      </joint>
      <actuator name="${parent}_${suffix}_wheel_motor">
        <hardwareInterface>hardware_interface/VelocityJointInterface</hardwareInterface>
        <mechanicalReduction>1</mechanicalReduction>
      </actuator>
    </transmission>
  </xacro:macro>

  <!-- Instantiate Left/Right Assemblies -->
  <xacro:rocker_bogie_assembly prefix="left" parent="base_link" reflect="1"/>
  <xacro:rocker_bogie_assembly prefix="right" parent="base_link" reflect="-1"/>

</robot>
