<?xml version="1.0"?>
<!-- This URDF was automatically created by SolidWorks to URDF Exporter! Originally created by Stephen Brawner (brawner@gmail.com) 
     Commit Version: 1.6.0-4-g7f85cfe  Build Version: 1.6.7995.38578
     For more information, please see http://wiki.ros.org/sw_urdf_exporter -->
<robot name="finalassemdoneright">
  <link name="rover_base">
    <inertial>
      <origin xyz="-0.215633362072026 9.56646294919539E-06 -0.0191770149708499" rpy="0 0 0" />
      <mass value="3.38632551346396" />
      <inertia ixx="0.0339951534702215" ixy="4.07301137981989E-07" ixz="2.1569330359615E-09" iyy="0.0473454419155019" iyz="-1.19495167767491E-10" izz="0.0801303818373678" />
    </inertial>
    <visual>
      <origin xyz="0 0 0" rpy="0 0 0" />
      <geometry>
        <mesh filename="package://finalassemdoneright/meshes/rover_base.STL" />
      </geometry>
      <material name="">
        <color rgba="0.647058823529412 0.619607843137255 0.588235294117647 1" />
      </material>
    </visual>
    <collision>
      <origin xyz="0 0 0" rpy="0 0 0" />
      <geometry>
        <mesh filename="package://finalassemdoneright/meshes/rover_base.STL" />
      </geometry>
    </collision>
  </link>
  <link name="Left_arm">
    <inertial>
      <origin xyz="-0.000256566433952554 0.0831497310894191 -0.000723080155142997" rpy="0 0 0" />
      <mass value="3.92316481248626" />
      <inertia ixx="0.0052807689036577" ixy="6.52589354477702E-08" ixz="9.75504870574046E-11" iyy="0.106186347196482" iyz="1.4999457750013E-10" izz="0.108137196053463" />
    </inertial>
    <visual>
      <origin xyz="0 0 0" rpy="0 0 0" />
      <geometry>
        <mesh filename="package://finalassemdoneright/meshes/Left_arm.STL" />
      </geometry>
      <material name="">
        <color rgba="0.529411764705882 0.549019607843137 0.549019607843137 1" />
      </material>
    </visual>
    <collision>
      <origin xyz="0 0 0" rpy="0 0 0" />
      <geometry>
        <mesh filename="package://finalassemdoneright/meshes/Left_arm.STL" />
      </geometry>
    </collision>
  </link>
  <joint name="LeftArm" type="revolute">
    <origin xyz="-0.0030459 0.3865 -0.019177" rpy="-1.5708 0.02417 -3.9896E-05" />
    <parent link="rover_base" />
    <child link="Left_arm" />
    <axis xyz="0 0 -1" />
    <limit lower="0" upper="0" effort="0" velocity="0" />
  </joint>
  <link name="Front_left_wheel">
    <inertial>
      <origin xyz="3.38719052805914E-09 1.95898309296449E-07 0.00123583012451922" rpy="0 0 0" />
      <mass value="2.15759144628966" />
      <inertia ixx="0.0193867868934573" ixy="-3.68743577331306E-08" ixz="2.28589587219819E-08" iyy="0.0193867834497432" iyz="-7.59597356737873E-09" izz="0.035931581449621" />
    </inertial>
    <visual>
      <origin xyz="0 0 0" rpy="0 0 0" />
      <geometry>
        <mesh filename="package://finalassemdoneright/meshes/Front_left_wheel.STL" />
      </geometry>
      <material name="">
        <color rgba="0.529411764705882 0.549019607843137 0.549019607843137 1" />
      </material>
    </visual>
    <collision>
      <origin xyz="0 0 0" rpy="0 0 0" />
      <geometry>
        <mesh filename="package://finalassemdoneright/meshes/Front_left_wheel.STL" />
      </geometry>
    </collision>
  </link>
  <joint name="FrontLeftWheel" type="continuous">
    <origin xyz="0.500099209351754 0.244618225407582 -0.000762000000002039" rpy="0 0 -0.0241704449199232" />
    <parent link="Left_arm" />
    <child link="Front_left_wheel" />
    <axis xyz="0 0 1" />
  </joint>
  <link name="Rear_left_wheel">
    <inertial>
      <origin xyz="3.38719002845878E-09 1.95898309074405E-07 0.00123583012451955" rpy="0 0 0" />
      <mass value="2.15759144628965" />
      <inertia ixx="0.0193867868934574" ixy="-3.68743577242217E-08" ixz="2.28589587246662E-08" iyy="0.019386783449743" iyz="-7.59597356728696E-09" izz="0.0359315814496209" />
    </inertial>
    <visual>
      <origin xyz="0 0 0" rpy="0 0 0" />
      <geometry>
        <mesh filename="package://finalassemdoneright/meshes/Rear_left_wheel.STL" />
      </geometry>
      <material name="">
        <color rgba="0.529411764705882 0.549019607843137 0.549019607843137 1" />
      </material>
    </visual>
    <collision>
      <origin xyz="0 0 0" rpy="0 0 0" />
      <geometry>
        <mesh filename="package://finalassemdoneright/meshes/Rear_left_wheel.STL" />
      </geometry>
    </collision>
  </link>
  <joint name="RearLeftWheel" type="continuous">
    <origin xyz="-0.500660790648241 0.244618225407579 -0.000762000000000707" rpy="0 0 -0.0241704449199232" />
    <parent link="Left_arm" />
    <child link="Rear_left_wheel" />
    <axis xyz="0 0 1" />
  </joint>
  <link name="Right_arm">
    <inertial>
      <origin xyz="-0.00231308206858527 0.0831179478688312 -0.000723080155048211" rpy="0 0 0" />
      <mass value="3.92316481243412" />
      <inertia ixx="0.00534249487807238" ixy="-0.00249493187347114" ixz="9.3806783112558E-11" iyy="0.106124621225874" iyz="1.52360423948609E-10" izz="0.10813719605729" />
    </inertial>
    <visual>
      <origin xyz="0 0 0" rpy="0 0 0" />
      <geometry>
        <mesh filename="package://finalassemdoneright/meshes/Right_arm.STL" />
      </geometry>
      <material name="">
        <color rgba="0.898039215686275 0.917647058823529 0.929411764705882 1" />
      </material>
    </visual>
    <collision>
      <origin xyz="0 0 0" rpy="0 0 0" />
      <geometry>
        <mesh filename="package://finalassemdoneright/meshes/Right_arm.STL" />
      </geometry>
    </collision>
  </link>
  <joint name="RightArm" type="revolute">
    <origin xyz="-0.0030767 -0.38676 -0.019177" rpy="-1.5708 0 -3.9896E-05" />
    <parent link="rover_base" />
    <child link="Right_arm" />
    <axis xyz="0 0 1" />
    <limit lower="0" upper="0" effort="0" velocity="0" />
  </joint>
  <link name="Front_right_wheel">
    <inertial>
      <origin xyz="7.94071999266066E-08 1.11401112168341E-07 0.0012358239781311" rpy="0 0 0" />
      <mass value="2.15759094085748" />
      <inertia ixx="0.0193867614947669" ixy="-2.32531028203293E-08" ixz="2.21377761754815E-08" iyy="0.0193868129604204" iyz="-1.68070612577714E-08" izz="0.0359315855993195" />
    </inertial>
    <visual>
      <origin xyz="0 0 0" rpy="0 0 0" />
      <geometry>
        <mesh filename="package://finalassemdoneright/meshes/Front_right_wheel.STL" />
      </geometry>
      <material name="">
        <color rgba="0.529411764705882 0.549019607843137 0.549019607843137 1" />
      </material>
    </visual>
    <collision>
      <origin xyz="0 0 0" rpy="0 0 0" />
      <geometry>
        <mesh filename="package://finalassemdoneright/meshes/Front_right_wheel.STL" />
      </geometry>
    </collision>
  </link>
  <joint name="FrontRightWheel" type="continuous">
    <origin xyz="0.493895922533436 0.256912656559873 -0.000762000000002372" rpy="0 0 0" />
    <parent link="Right_arm" />
    <child link="Front_right_wheel" />
    <axis xyz="0 0 1" />
  </joint>
  <link name="Rear_right_wheel">
    <inertial>
      <origin xyz="3.38719058357029E-09 1.95898309296449E-07 0.00123583012451853" rpy="0 0 0" />
      <mass value="2.15759144628968" />
      <inertia ixx="0.0193867868934575" ixy="-3.68743577382929E-08" ixz="2.28589587110465E-08" iyy="0.0193867834497432" iyz="-7.59597356524807E-09" izz="0.0359315814496211" />
    </inertial>
    <visual>
      <origin xyz="0 0 0" rpy="0 0 0" />
      <geometry>
        <mesh filename="package://finalassemdoneright/meshes/Rear_right_wheel.STL" />
      </geometry>
      <material name="">
        <color rgba="0.529411764705882 0.549019607843137 0.549019607843137 1" />
      </material>
    </visual>
    <collision>
      <origin xyz="0 0 0" rpy="0 0 0" />
      <geometry>
        <mesh filename="package://finalassemdoneright/meshes/Rear_right_wheel.STL" />
      </geometry>
    </collision>
  </link>
  <joint name="RearRightWheel" type="continuous">
    <origin xyz="-0.506557922109957 0.232160235703112 -0.000762000000003649" rpy="0 0 0" />
    <parent link="Right_arm" />
    <child link="Rear_right_wheel" />
    <axis xyz="0 0 1" />
  </joint>
</robot>
